<sdf version='1.6'>
  <world name='default'>
    <light name='sun' type='directional'>
      <cast_shadows>1</cast_shadows>
      <pose frame=''>0 0 10 0 -0 0</pose>
      <diffuse>0.8 0.8 0.8 1</diffuse>
      <specular>0.2 0.2 0.2 1</specular>
      <attenuation>
        <range>1000</range>
        <constant>0.9</constant>
        <linear>0.01</linear>
        <quadratic>0.001</quadratic>
      </attenuation>
      <direction>-0.5 0.1 -0.9</direction>
    </light>
    <model name='ground_plane'>
      <static>1</static>
      <link name='link'>
        <collision name='collision'>
          <geometry>
            <plane>
              <normal>0 0 1</normal>
              <size>100 100</size>
            </plane>
          </geometry>
          <surface>
            <contact>
              <collide_bitmask>65535</collide_bitmask>
              <ode/>
            </contact>
            <friction>
              <ode>
                <mu>100</mu>
                <mu2>50</mu2>
              </ode>
              <torsional>
                <ode/>
              </torsional>
            </friction>
            <bounce/>
          </surface>
          <max_contacts>10</max_contacts>
        </collision>
        <visual name='visual'>
          <cast_shadows>0</cast_shadows>
          <geometry>
            <plane>
              <normal>0 0 1</normal>
              <size>100 100</size>
            </plane>
          </geometry>
          <material>
            <script>
              <uri>file://media/materials/scripts/gazebo.material</uri>
              <name>Gazebo/Grey</name>
            </script>
          </material>
        </visual>
        <self_collide>0</self_collide>
        <enable_wind>0</enable_wind>
        <kinematic>0</kinematic>
      </link>
    </model>
    <gravity>0 0 -9.8</gravity>
    <magnetic_field>6e-06 2.3e-05 -4.2e-05</magnetic_field>
    <atmosphere type='adiabatic'/>
    <physics name='default_physics' default='0' type='ode'>
      <max_step_size>0.001</max_step_size>
      <real_time_factor>1</real_time_factor>
      <real_time_update_rate>1000</real_time_update_rate>
    </physics>
    <scene>
      <ambient>0.4 0.4 0.4 1</ambient>
      <background>0.7 0.7 0.7 1</background>
      <shadows>1</shadows>
    </scene>
    <wind/>
    <spherical_coordinates>
      <surface_model>EARTH_WGS84</surface_model>
      <latitude_deg>0</latitude_deg>
      <longitude_deg>0</longitude_deg>
      <elevation>0</elevation>
      <heading_deg>0</heading_deg>
    </spherical_coordinates>
    <model name='test'>
      <model name='cart_front_steer'>
        <link name='chassis'>
          <pose frame=''>0 0 0.15 0 -0 0</pose>
          <inertial>
            <pose frame=''>0.1 0 0 0 -0 0</pose>
            <mass>10</mass>
            <inertia>
              <ixx>0.216667</ixx>
              <iyy>0.841667</iyy>
              <izz>1.04167</izz>
              <ixy>0</ixy>
              <ixz>0</ixz>
              <iyz>0</iyz>
            </inertia>
          </inertial>
          <collision name='collision'>
            <geometry>
              <box>
                <size>1 0.5 0.1</size>
              </box>
            </geometry>
            <max_contacts>10</max_contacts>
            <surface>
              <contact>
                <ode/>
              </contact>
              <bounce/>
              <friction>
                <torsional>
                  <ode/>
                </torsional>
                <ode/>
              </friction>
            </surface>
          </collision>
          <visual name='visual'>
            <geometry>
              <box>
                <size>1 0.5 0.1</size>
              </box>
            </geometry>
            <material>
              <script>
                <uri>file://media/materials/scripts/gazebo.material</uri>
                <name>Gazebo/Grey</name>
              </script>
            </material>
          </visual>
          <self_collide>0</self_collide>
          <enable_wind>0</enable_wind>
          <kinematic>0</kinematic>
        </link>
        <link name='wheel_front_left'>
          <pose frame=''>0.5 0.298 0.15 -1.5708 -0.087266 0</pose>
          <inertial>
            <mass>0.5</mass>
            <inertia>
              <ixx>0.00307917</ixx>
              <iyy>0.00307917</iyy>
              <izz>0.005625</izz>
              <ixy>0</ixy>
              <ixz>0</ixz>
              <iyz>0</iyz>
            </inertia>
            <pose frame=''>0 0 0 0 -0 0</pose>
          </inertial>
          <collision name='collision'>
            <geometry>
              <cylinder>
                <radius>0.15</radius>
                <length>0.08</length>
              </cylinder>
            </geometry>
            <max_contacts>10</max_contacts>
            <surface>
              <contact>
                <ode/>
              </contact>
              <bounce/>
              <friction>
                <torsional>
                  <ode/>
                </torsional>
                <ode/>
              </friction>
            </surface>
          </collision>
          <visual name='visual'>
            <geometry>
              <cylinder>
                <radius>0.15</radius>
                <length>0.08</length>
              </cylinder>
            </geometry>
            <material>
              <script>
                <uri>file://media/materials/scripts/gazebo.material</uri>
                <name>Gazebo/Black</name>
              </script>
            </material>
          </visual>
          <self_collide>0</self_collide>
          <enable_wind>0</enable_wind>
          <kinematic>0</kinematic>
        </link>
        <joint name='wheel_front_left_steer_spin' type='universal'>
          <parent>chassis</parent>
          <child>wheel_front_left</child>
          <axis>
            <xyz>0 -1 0</xyz>
            <limit>
              <lower>-0.610865</lower>
              <upper>0.610865</upper>
            </limit>
            <use_parent_model_frame>0</use_parent_model_frame>
            <dynamics>
              <spring_reference>0</spring_reference>
              <spring_stiffness>0</spring_stiffness>
            </dynamics>
          </axis>
          <axis2>
            <xyz>0 0 1</xyz>
            <use_parent_model_frame>0</use_parent_model_frame>
            <dynamics>
              <spring_reference>0</spring_reference>
              <spring_stiffness>0</spring_stiffness>
            </dynamics>
          </axis2>
        </joint>
        <link name='wheel_front_right'>
          <pose frame=''>0.5 -0.298 0.15 -1.5708 -0.087266 0</pose>
          <inertial>
            <mass>0.5</mass>
            <inertia>
              <ixx>0.00307917</ixx>
              <iyy>0.00307917</iyy>
              <izz>0.005625</izz>
              <ixy>0</ixy>
              <ixz>0</ixz>
              <iyz>0</iyz>
            </inertia>
            <pose frame=''>0 0 0 0 -0 0</pose>
          </inertial>
          <collision name='collision'>
            <geometry>
              <cylinder>
                <radius>0.15</radius>
                <length>0.08</length>
              </cylinder>
            </geometry>
            <max_contacts>10</max_contacts>
            <surface>
              <contact>
                <ode/>
              </contact>
              <bounce/>
              <friction>
                <torsional>
                  <ode/>
                </torsional>
                <ode/>
              </friction>
            </surface>
          </collision>
          <visual name='visual'>
            <geometry>
              <cylinder>
                <radius>0.15</radius>
                <length>0.08</length>
              </cylinder>
            </geometry>
            <material>
              <script>
                <uri>file://media/materials/scripts/gazebo.material</uri>
                <name>Gazebo/Black</name>
              </script>
            </material>
          </visual>
          <self_collide>0</self_collide>
          <enable_wind>0</enable_wind>
          <kinematic>0</kinematic>
        </link>
        <joint name='wheel_front_right_steer_spin' type='universal'>
          <parent>chassis</parent>
          <child>wheel_front_right</child>
          <axis>
            <xyz>0 -1 0</xyz>
            <limit>
              <lower>-0.610865</lower>
              <upper>0.610865</upper>
            </limit>
            <use_parent_model_frame>0</use_parent_model_frame>
            <dynamics>
              <spring_reference>0</spring_reference>
              <spring_stiffness>0</spring_stiffness>
            </dynamics>
          </axis>
          <axis2>
            <xyz>0 0 1</xyz>
            <use_parent_model_frame>0</use_parent_model_frame>
            <dynamics>
              <spring_reference>0</spring_reference>
              <spring_stiffness>0</spring_stiffness>
            </dynamics>
          </axis2>
        </joint>
        <link name='wheel_rear_left'>
          <pose frame=''>-0.5 0.298 0.15 -1.5708 0 0</pose>
          <inertial>
            <mass>0.5</mass>
            <inertia>
              <ixx>0.00307917</ixx>
              <iyy>0.00307917</iyy>
              <izz>0.005625</izz>
              <ixy>0</ixy>
              <ixz>0</ixz>
              <iyz>0</iyz>
            </inertia>
            <pose frame=''>0 0 0 0 -0 0</pose>
          </inertial>
          <collision name='collision'>
            <geometry>
              <cylinder>
                <radius>0.15</radius>
                <length>0.08</length>
              </cylinder>
            </geometry>
            <max_contacts>10</max_contacts>
            <surface>
              <contact>
                <ode/>
              </contact>
              <bounce/>
              <friction>
                <torsional>
                  <ode/>
                </torsional>
                <ode/>
              </friction>
            </surface>
          </collision>
          <visual name='visual'>
            <geometry>
              <cylinder>
                <radius>0.15</radius>
                <length>0.08</length>
              </cylinder>
            </geometry>
            <material>
              <script>
                <uri>file://media/materials/scripts/gazebo.material</uri>
                <name>Gazebo/Black</name>
              </script>
            </material>
          </visual>
          <self_collide>0</self_collide>
          <enable_wind>0</enable_wind>
          <kinematic>0</kinematic>
        </link>
        <joint name='wheel_rear_left_spin' type='revolute'>
          <parent>chassis</parent>
          <child>wheel_rear_left</child>
          <axis>
            <xyz>0 0 1</xyz>
            <use_parent_model_frame>0</use_parent_model_frame>
            <limit>
              <lower>-1e+16</lower>
              <upper>1e+16</upper>
            </limit>
            <dynamics>
              <spring_reference>0</spring_reference>
              <spring_stiffness>0</spring_stiffness>
            </dynamics>
          </axis>
        </joint>
        <link name='wheel_rear_right'>
          <pose frame=''>-0.5 -0.298 0.15 -1.5708 0 0</pose>
          <inertial>
            <mass>0.5</mass>
            <inertia>
              <ixx>0.00307917</ixx>
              <iyy>0.00307917</iyy>
              <izz>0.005625</izz>
              <ixy>0</ixy>
              <ixz>0</ixz>
              <iyz>0</iyz>
            </inertia>
            <pose frame=''>0 0 0 0 -0 0</pose>
          </inertial>
          <collision name='collision'>
            <geometry>
              <cylinder>
                <radius>0.15</radius>
                <length>0.08</length>
              </cylinder>
            </geometry>
            <max_contacts>10</max_contacts>
            <surface>
              <contact>
                <ode/>
              </contact>
              <bounce/>
              <friction>
                <torsional>
                  <ode/>
                </torsional>
                <ode/>
              </friction>
            </surface>
          </collision>
          <visual name='visual'>
            <geometry>
              <cylinder>
                <radius>0.15</radius>
                <length>0.08</length>
              </cylinder>
            </geometry>
            <material>
              <script>
                <uri>file://media/materials/scripts/gazebo.material</uri>
                <name>Gazebo/Black</name>
              </script>
            </material>
          </visual>
          <self_collide>0</self_collide>
          <enable_wind>0</enable_wind>
          <kinematic>0</kinematic>
        </link>
        <joint name='wheel_rear_right_spin' type='revolute'>
          <parent>chassis</parent>
          <child>wheel_rear_right</child>
          <axis>
            <xyz>0 0 1</xyz>
            <use_parent_model_frame>0</use_parent_model_frame>
            <limit>
              <lower>-1e+16</lower>
              <upper>1e+16</upper>
            </limit>
            <dynamics>
              <spring_reference>0</spring_reference>
              <spring_stiffness>0</spring_stiffness>
            </dynamics>
          </axis>
        </joint>
        <pose frame=''>-0.2 0 -0.2 -0 -0 -0</pose>
      </model>
      <model name='kinect'>
        <plugin name='name_gps' filename='libhector_gazebo_ros_gps.so'>
          <alwayson>1</alwayson>
          <updaterate>10.0</updaterate>
          <bodyname>basefootprint</bodyname>
          <topicname>fix</topicname>
          <velocitytopicname>fixvelocity</velocitytopicname>
          <drift>5.0 5.0 5.0</drift>
          <gaussiannoise>0.1 0.1 0.1</gaussiannoise>
          <velocitydrift>0 0 0</velocitydrift>
          <velocitygaussiannoise>0.1 0.1 0.1</velocitygaussiannoise>
        </plugin>
        <pose frame=''>0.2 -0 0.2 -0 -0 -0</pose>
        <link name='link'>
          <inertial>
            <mass>0.1</mass>
            <pose frame=''>0 0 0 0 -0 0</pose>
            <inertia>
              <ixx>1</ixx>
              <ixy>0</ixy>
              <ixz>0</ixz>
              <iyy>1</iyy>
              <iyz>0</iyz>
              <izz>1</izz>
            </inertia>
          </inertial>
          <collision name='collision'>
            <geometry>
              <box>
                <size>0.073 0.276 0.072</size>
              </box>
            </geometry>
            <max_contacts>10</max_contacts>
            <surface>
              <contact>
                <ode/>
              </contact>
              <bounce/>
              <friction>
                <torsional>
                  <ode/>
                </torsional>
                <ode/>
              </friction>
            </surface>
          </collision>
          <visual name='visual'>
            <geometry>
              <mesh>
                <uri>model://kinect/meshes/kinect.dae</uri>
              </mesh>
            </geometry>
          </visual>
          <gravity>1</gravity>
          <sensor name='imu_sensor' type='imu'>
            <always_on>1</always_on>
            <update_rate>100</update_rate>
            <visualize>1</visualize>
            <topic>__default_topic__</topic>
            <plugin name='imu_plugin' filename='libgazebo_ros_imu_sensor.so'>
              <topicName>imu</topicName>
              <bodyName>imu_link</bodyName>
              <updateRateHZ>10.0</updateRateHZ>
              <gaussianNoise>0.0</gaussianNoise>
              <xyzOffset>0 0 0</xyzOffset>
              <rpyOffset>0 0 0</rpyOffset>
              <frameName>imu_link</frameName>
            </plugin>
            <pose frame=''>0 0 0 0 -0 0</pose>
            <imu/>
          </sensor>
          <sensor name='camera' type='depth'>
            <plugin name='camera_plugin' filename='libgazebo_ros_openni_kinect.so'>
              <baseline>0.2</baseline>
              <alwaysOn>1</alwaysOn>
              <updateRate>0.0</updateRate>
              <cameraName>camera_ir</cameraName>
              <imageTopicName>/camera/color/image_raw</imageTopicName>
              <cameraInfoTopicName>/camera/color/camera_info</cameraInfoTopicName>
              <depthImageTopicName>/camera/depth/image_raw</depthImageTopicName>
              <depthImageCameraInfoTopicName>/camera/depth/camera_info</depthImageCameraInfoTopicName>
              <pointCloudTopicName>/camera/depth/points</pointCloudTopicName>
              <frameName>camera_link</frameName>
              <pointCloudCutoff>0.5</pointCloudCutoff>
              <pointCloudCutoffMax>3.0</pointCloudCutoffMax>
              <distortionK1>0</distortionK1>
              <distortionK2>0</distortionK2>
              <distortionK3>0</distortionK3>
              <distortionT1>0</distortionT1>
              <distortionT2>0</distortionT2>
              <CxPrime>0</CxPrime>
              <Cx>0</Cx>
              <Cy>0</Cy>
              <focalLength>0</focalLength>
              <hackBaseline>0</hackBaseline>
            </plugin>
            <update_rate>20</update_rate>
            <camera name='__default__'>
              <horizontal_fov>1.0472</horizontal_fov>
              <image>
                <width>640</width>
                <height>480</height>
                <format>R8G8B8</format>
              </image>
              <clip>
                <near>0.05</near>
                <far>3</far>
              </clip>
            </camera>
          </sensor>
          <self_collide>0</self_collide>
          <enable_wind>0</enable_wind>
          <kinematic>0</kinematic>
        </link>
      </model>
      <joint name='chassis_JOINT_1' type='fixed'>
        <parent>cart_front_steer::chassis</parent>
        <child>kinect::link</child>
        <pose frame=''>-0.38 0 0.2 0 -0 0</pose>
        <physics>
          <ode>
            <limit>
              <cfm>0</cfm>
              <erp>0.2</erp>
            </limit>
            <suspension>
              <cfm>0</cfm>
              <erp>0.2</erp>
            </suspension>
          </ode>
        </physics>
      </joint>
      <static>0</static>
      <allow_auto_disable>0</allow_auto_disable>
      <pose frame=''>-2.90105 -0.225101 0 0 -0 0</pose>
    </model>
    <model name='unit_box'>
      <pose frame=''>-0.448058 -0.439717 0.5 0 -0 0</pose>
      <link name='link'>
        <inertial>
          <mass>1</mass>
          <inertia>
            <ixx>0.166667</ixx>
            <ixy>0</ixy>
            <ixz>0</ixz>
            <iyy>0.166667</iyy>
            <iyz>0</iyz>
            <izz>0.166667</izz>
          </inertia>
          <pose frame=''>0 0 0 0 -0 0</pose>
        </inertial>
        <collision name='collision'>
          <geometry>
            <box>
              <size>1 1 1</size>
            </box>
          </geometry>
          <max_contacts>10</max_contacts>
          <surface>
            <contact>
              <ode/>
            </contact>
            <bounce/>
            <friction>
              <torsional>
                <ode/>
              </torsional>
              <ode/>
            </friction>
          </surface>
        </collision>
        <visual name='visual'>
          <geometry>
            <box>
              <size>1 1 1</size>
            </box>
          </geometry>
          <material>
            <script>
              <name>Gazebo/Grey</name>
              <uri>file://media/materials/scripts/gazebo.material</uri>
            </script>
          </material>
        </visual>
        <self_collide>0</self_collide>
        <enable_wind>0</enable_wind>
        <kinematic>0</kinematic>
      </link>
    </model>
    <model name='unit_sphere'>
      <pose frame=''>-0.165771 0.469946 0.5 0 -0 0</pose>
      <link name='link'>
        <inertial>
          <mass>1</mass>
          <inertia>
            <ixx>0.1</ixx>
            <ixy>0</ixy>
            <ixz>0</ixz>
            <iyy>0.1</iyy>
            <iyz>0</iyz>
            <izz>0.1</izz>
          </inertia>
          <pose frame=''>0 0 0 0 -0 0</pose>
        </inertial>
        <collision name='collision'>
          <geometry>
            <sphere>
              <radius>0.5</radius>
            </sphere>
          </geometry>
          <max_contacts>10</max_contacts>
          <surface>
            <contact>
              <ode/>
            </contact>
            <bounce/>
            <friction>
              <torsional>
                <ode/>
              </torsional>
              <ode/>
            </friction>
          </surface>
        </collision>
        <visual name='visual'>
          <geometry>
            <sphere>
              <radius>0.5</radius>
            </sphere>
          </geometry>
          <material>
            <script>
              <name>Gazebo/Grey</name>
              <uri>file://media/materials/scripts/gazebo.material</uri>
            </script>
          </material>
        </visual>
        <self_collide>0</self_collide>
        <enable_wind>0</enable_wind>
        <kinematic>0</kinematic>
      </link>
    </model>
    <state world_name='default'>
      <sim_time>95 99000000</sim_time>
      <real_time>96 613413298</real_time>
      <wall_time>1569831675 665853755</wall_time>
      <iterations>95099</iterations>
      <model name='ground_plane'>
        <pose frame=''>0 0 0 0 -0 0</pose>
        <scale>1 1 1</scale>
        <link name='link'>
          <pose frame=''>0 0 0 0 -0 0</pose>
          <velocity>0 0 0 0 -0 0</velocity>
          <acceleration>0 0 0 0 -0 0</acceleration>
          <wrench>0 0 0 0 -0 0</wrench>
        </link>
      </model>
      <model name='test'>
        <pose frame=''>-2.89057 -0.216522 0.199997 0 -1.1e-05 0.004117</pose>
        <scale>1 1 1</scale>
        <model name='cart_front_steer'>
          <pose frame=''>-3.09057 -0.217345 -5e-06 0 -1.1e-05 0.004117</pose>
          <scale>1 1 1</scale>
          <link name='chassis'>
            <pose frame=''>-3.09057 -0.217345 0.149995 0 -1.1e-05 0.004117</pose>
            <velocity>-0.000684 -0.000418 -0.005387 0.000175 -0.0108 4.7e-05</velocity>
            <acceleration>-0.012207 -0.382269 -4.75914 -2.70634 0.904891 2.48948</acceleration>
            <wrench>-0.122071 -3.82269 -47.5914 0 -0 0</wrench>
          </link>
          <link name='wheel_front_left'>
            <pose frame=''>-2.5918 0.08271 0.15 -1.57081 0.527313 0.003955</pose>
            <velocity>-0.000695 -0.000349 1e-06 0.002379 -0.002886 -0.006553</velocity>
            <acceleration>0.181274 -0.579166 -0.37476 0.686507 0.22911 0.185514</acceleration>
            <wrench>0.090637 -0.289583 -0.18738 0 -0 0</wrench>
          </link>
          <link name='wheel_front_right'>
            <pose frame=''>-2.58935 -0.513284 0.15 -1.5708 0.476555 0.004158</pose>
            <velocity>-0.00069 -0.000371 -4.6e-05 0.002419 0.00282 -0.027828</velocity>
            <acceleration>-0.207591 -0.504505 -0.861025 0.180349 -0.202367 -1.38434</acceleration>
            <wrench>-0.103796 -0.252253 -0.430512 0 -0 0</wrench>
          </link>
          <link name='wheel_rear_left'>
            <pose frame=''>-3.59179 0.078593 0.14999 -1.5708 0.038533 0.004117</pose>
            <velocity>-0.000696 -0.000379 -0.010751 0.000397 -0.006192 0.000176</velocity>
            <acceleration>0.193968 -0.056721 -10.9417 -1.73329 -0.00714 -1.37709</acceleration>
            <wrench>0.096984 -0.02836 -5.47084 0 -0 0</wrench>
          </link>
          <link name='wheel_rear_right'>
            <pose frame=''>-3.58934 -0.517402 0.149989 -1.5708 0.045387 0.004116</pose>
            <velocity>-0.00067 -0.000416 -0.010849 0.000453 -0.003212 0.000171</velocity>
            <acceleration>-0.221713 -0.099591 -10.9625 -1.61855 -0.006667 -1.19819</acceleration>
            <wrench>-0.110857 -0.049795 -5.48127 0 -0 0</wrench>
          </link>
        </model>
        <model name='kinect'>
          <pose frame=''>-2.70105 -0.225101 0.2 0 -0 0</pose>
          <scale>1 1 1</scale>
          <link name='link'>
            <pose frame=''>-2.69057 -0.215699 0.399999 0 -1.1e-05 0.004117</pose>
            <velocity>-0.003388 -0.000447 -0.001058 0.000178 -0.010811 4.9e-05</velocity>
            <acceleration>-2.59313 -0.732606 -1.66107 -2.56684 0.90376 2.46841</acceleration>
            <wrench>-0.259313 -0.073261 -0.166107 0 -0 0</wrench>
          </link>
        </model>
      </model>
      <model name='unit_box'>
        <pose frame=''>-0.448057 -0.439716 0.5 -1e-06 0 -0.420749</pose>
        <scale>1 0.125965 1</scale>
        <link name='link'>
          <pose frame=''>-0.448057 -0.439716 0.5 -1e-06 0 -0.420749</pose>
          <velocity>0 0 0 0 -0 0</velocity>
          <acceleration>-5.80778 3.02791 6.453 0.228144 0.949996 -0.001417</acceleration>
          <wrench>-5.80778 3.02791 6.453 0 -0 0</wrench>
        </link>
      </model>
      <model name='unit_sphere'>
        <pose frame=''>-1.42329 0.469946 0.198095 0 -0 0</pose>
        <scale>0.39619 0.39619 0.39619</scale>
        <link name='link'>
          <pose frame=''>-1.42329 0.469946 0.198095 0 -0 0</pose>
          <velocity>0 0 0 0 -0 0</velocity>
          <acceleration>0 0 0 0 -0 0</acceleration>
          <wrench>0 0 0 0 -0 0</wrench>
        </link>
      </model>
      <light name='sun'>
        <pose frame=''>0 0 10 0 -0 0</pose>
      </light>
    </state>
    <gui fullscreen='0'>
      <camera name='user_camera'>
        <pose frame=''>5.70401 2.71688 4.8233 0 0.710362 -2.65913</pose>
        <view_controller>orbit</view_controller>
        <projection_type>perspective</projection_type>
      </camera>
    </gui>
  </world>
</sdf>
